[2021-01-15 16:29:57,713] {taskinstance.py:670} INFO - Dependencies all met for <TaskInstance: slack_dag.fail_py 2021-01-14T00:00:00+00:00 [queued]>
[2021-01-15 16:29:57,720] {taskinstance.py:670} INFO - Dependencies all met for <TaskInstance: slack_dag.fail_py 2021-01-14T00:00:00+00:00 [queued]>
[2021-01-15 16:29:57,720] {taskinstance.py:880} INFO - 
--------------------------------------------------------------------------------
[2021-01-15 16:29:57,720] {taskinstance.py:881} INFO - Starting attempt 1 of 2
[2021-01-15 16:29:57,720] {taskinstance.py:882} INFO - 
--------------------------------------------------------------------------------
[2021-01-15 16:29:57,725] {taskinstance.py:901} INFO - Executing <Task(PythonOperator): fail_py> on 2021-01-14T00:00:00+00:00
[2021-01-15 16:29:57,727] {standard_task_runner.py:54} INFO - Started process 8874 to run task
[2021-01-15 16:29:57,769] {standard_task_runner.py:77} INFO - Running: ['airflow', 'run', 'slack_dag', 'fail_py', '2021-01-14T00:00:00+00:00', '--job_id', '45', '--pool', 'default_pool', '--raw', '-sd', 'DAGS_FOLDER/slack_noti.py', '--cfg_path', '/var/folders/4f/xnn880bn51d9945mdydbgwdw0000gn/T/tmpnkxm0jwc']
[2021-01-15 16:29:57,771] {standard_task_runner.py:78} INFO - Job 45: Subtask fail_py
[2021-01-15 16:29:57,792] {logging_mixin.py:112} INFO - Running <TaskInstance: slack_dag.fail_py 2021-01-14T00:00:00+00:00 [running]> on host 1.0.0.0.0.0.0.0.0.0.0.0.0.0.0.0.0.0.0.0.0.0.0.0.0.0.0.0.0.0.0.0.ip6.arpa
[2021-01-15 16:29:57,802] {taskinstance.py:1150} ERROR - division by zero
Traceback (most recent call last):
  File "/Users/ichiro/.pyenv/versions/3.9.1/lib/python3.9/site-packages/airflow/models/taskinstance.py", line 984, in _run_raw_task
    result = task_copy.execute(context=context)
  File "/Users/ichiro/.pyenv/versions/3.9.1/lib/python3.9/site-packages/airflow/operators/python_operator.py", line 113, in execute
    return_value = self.execute_callable()
  File "/Users/ichiro/.pyenv/versions/3.9.1/lib/python3.9/site-packages/airflow/operators/python_operator.py", line 118, in execute_callable
    return self.python_callable(*self.op_args, **self.op_kwargs)
  File "/Users/ichiro/airflow/dags/slack_noti.py", line 40, in fail_py
    1/0
ZeroDivisionError: division by zero
[2021-01-15 16:29:57,803] {taskinstance.py:1187} INFO - Marking task as UP_FOR_RETRY. dag_id=slack_dag, task_id=fail_py, execution_date=20210114T000000, start_date=20210115T072957, end_date=20210115T072957
[2021-01-15 16:30:02,715] {local_task_job.py:102} INFO - Task exited with return code 1
