[2021-01-15 16:31:39,469] {taskinstance.py:670} INFO - Dependencies all met for <TaskInstance: slack_dag.fail_py 2021-01-14T00:00:00+00:00 [queued]>
[2021-01-15 16:31:39,476] {taskinstance.py:670} INFO - Dependencies all met for <TaskInstance: slack_dag.fail_py 2021-01-14T00:00:00+00:00 [queued]>
[2021-01-15 16:31:39,476] {taskinstance.py:880} INFO - 
--------------------------------------------------------------------------------
[2021-01-15 16:31:39,476] {taskinstance.py:881} INFO - Starting attempt 2 of 2
[2021-01-15 16:31:39,476] {taskinstance.py:882} INFO - 
--------------------------------------------------------------------------------
[2021-01-15 16:31:39,481] {taskinstance.py:901} INFO - Executing <Task(PythonOperator): fail_py> on 2021-01-14T00:00:00+00:00
[2021-01-15 16:31:39,485] {standard_task_runner.py:54} INFO - Started process 8944 to run task
[2021-01-15 16:31:39,529] {standard_task_runner.py:77} INFO - Running: ['airflow', 'run', 'slack_dag', 'fail_py', '2021-01-14T00:00:00+00:00', '--job_id', '52', '--pool', 'default_pool', '--raw', '-sd', 'DAGS_FOLDER/slack_noti.py', '--cfg_path', '/var/folders/4f/xnn880bn51d9945mdydbgwdw0000gn/T/tmptsih9hhf']
[2021-01-15 16:31:39,530] {standard_task_runner.py:78} INFO - Job 52: Subtask fail_py
[2021-01-15 16:31:39,552] {logging_mixin.py:112} INFO - Running <TaskInstance: slack_dag.fail_py 2021-01-14T00:00:00+00:00 [running]> on host 1.0.0.0.0.0.0.0.0.0.0.0.0.0.0.0.0.0.0.0.0.0.0.0.0.0.0.0.0.0.0.0.ip6.arpa
[2021-01-15 16:31:39,562] {taskinstance.py:1150} ERROR - division by zero
Traceback (most recent call last):
  File "/Users/ichiro/.pyenv/versions/3.9.1/lib/python3.9/site-packages/airflow/models/taskinstance.py", line 984, in _run_raw_task
    result = task_copy.execute(context=context)
  File "/Users/ichiro/.pyenv/versions/3.9.1/lib/python3.9/site-packages/airflow/operators/python_operator.py", line 113, in execute
    return_value = self.execute_callable()
  File "/Users/ichiro/.pyenv/versions/3.9.1/lib/python3.9/site-packages/airflow/operators/python_operator.py", line 118, in execute_callable
    return self.python_callable(*self.op_args, **self.op_kwargs)
  File "/Users/ichiro/airflow/dags/slack_noti.py", line 40, in fail_py
    1/0
ZeroDivisionError: division by zero
[2021-01-15 16:31:39,564] {taskinstance.py:1187} INFO - Marking task as FAILED. dag_id=slack_dag, task_id=fail_py, execution_date=20210114T000000, start_date=20210115T073139, end_date=20210115T073139
[2021-01-15 16:31:39,564] {logging_mixin.py:112} INFO - aaaaaaaaaatest
[2021-01-15 16:31:44,472] {local_task_job.py:102} INFO - Task exited with return code Negsignal.SIGABRT
